Workbook

Sheet 요약
A1: M2M-AT / OTH-AT 기능 구현 비교 및 시험 결과
A2: 작성 2026-10-06. M2M: ESP32_C3 (GitHub M2M_ESP32_C3) / OTH: OTH_ESP32_C3 (GitHub OTH_ESP32_C, 626e615). 같은 펌웨어 소스에서 Kconfig로 명령 세트 선택
A4: 명령 상태 집계 (각 결과 시트의 상태 열을 수식으로 집계)
A5: 상태 | B5: M2M-AT 명령 | C5: M2M 비율 | D5: OTH-AT 명령 | E5: OTH 비율
A6: 검증완료 | B6: =COUNTIF('M2M 명령 결과'!$E$5:$E$70,A6) -> 61 | C6: =IF($B$12=0,0,B6/$B$12) -> 0.92424242 | D6: =COUNTIF('OTH 명령 결과'!$D$5:$D$69,A6) -> 54 | E6: =IF($D$12=0,0,D6/$D$12) -> 0.83076923
A7: 부분검증 | B7: =COUNTIF('M2M 명령 결과'!$E$5:$E$70,A7) -> 0 | C7: =IF($B$12=0,0,B7/$B$12) -> 0 | D7: =COUNTIF('OTH 명령 결과'!$D$5:$D$69,A7) -> 1 | E7: =IF($D$12=0,0,D7/$D$12) -> 0.015384615
A8: 미검증 | B8: =COUNTIF('M2M 명령 결과'!$E$5:$E$70,A8) -> 2 | C8: =IF($B$12=0,0,B8/$B$12) -> 0.03030303 | D8: =COUNTIF('OTH 명령 결과'!$D$5:$D$69,A8) -> 2 | E8: =IF($D$12=0,0,D8/$D$12) -> 0.030769231
A9: 미구현 | B9: =COUNTIF('M2M 명령 결과'!$E$5:$E$70,A9) -> 1 | C9: =IF($B$12=0,0,B9/$B$12) -> 0.015151515 | D9: =COUNTIF('OTH 명령 결과'!$D$5:$D$69,A9) -> 1 | E9: =IF($D$12=0,0,D9/$D$12) -> 0.015384615
A10: 미지원 | B10: =COUNTIF('M2M 명령 결과'!$E$5:$E$70,A10) -> 0 | C10: =IF($B$12=0,0,B10/$B$12) -> 0 | D10: =COUNTIF('OTH 명령 결과'!$D$5:$D$69,A10) -> 7 | E10: =IF($D$12=0,0,D10/$D$12) -> 0.10769231
A11: 기타 | B11: =COUNTIF('M2M 명령 결과'!$E$5:$E$70,A11) -> 2 | C11: =IF($B$12=0,0,B11/$B$12) -> 0.03030303 | D11: =COUNTIF('OTH 명령 결과'!$D$5:$D$69,A11) -> 0 | E11: =IF($D$12=0,0,D11/$D$12) -> 0
A12: 합계 | B12: =SUM(B6:B11) -> 66 | C12: =SUM(C6:C11) -> 1 | D12: =SUM(D6:D11) -> 65 | E12: =SUM(E6:E11) -> 1
A13: ※ M2M 66건(Ch.2~6 + 프로젝트 추가 명령), OTH는 명령 묶음 단위 행. OTH AWS 볼륨은 2026-10-06 재구현 결과(추가 명령 포함).
A15: OTH Platform 시험 (2026-10-06)
A16: 판정 | B16: 건수
A17: 합격 | B17: =COUNTIF('OTH Platform 시험'!$F$5:$F$25,A17) -> 17
A18: 합격(관찰사항) | B18: =COUNTIF('OTH Platform 시험'!$F$5:$F$25,A18) -> 1
A19: 미시험 | B19: =COUNTIF('OTH Platform 시험'!$F$5:$F$25,A19) -> 3
A20: 합계 | B20: =SUM(B17:B19) -> 21
A22: 핵심 차이
A23: 1. 명령 체계: M2M-AT(AT*M2M*, 기능별 세분 명령) vs OTH-AT(AT*OTH*, Essentials/MQTT/AWS 볼륨). Wi-Fi·소켓·HTTP·MQTT·보안 코드는 공용.
A24: 2. AWS: M2M은 AWS 표준 Fleet Provisioning + 임의 토픽 발행/구독(호스트 주도). OTH는 OTH Platform 전용 - SoftAP 페어링 → 인증서버 → 고정 토픽/봉투, 모듈이 자동 접속·FOTA 처리.
A25: 3. 펌웨어: OTH만 XMODEM(FWUPGRADE), 클라우드 암호화 FOTA, MCU 펌웨어 중계(MOTA_*) 제공.
A26: 4. 소켓: M2M net_link.c(링크 0~3) / OTH oth_sock.c(TCP 0-2, UDP 3-5, SSL 6) 별도 엔진.
A27: 5. 프로비저닝: M2M은 BLE(BLE_PROV), OTH는 SoftAP TCP 47000 페어링.
A28: 6. 이미지 ID: M2M _MM_ / OTH _OT_ → 서로의 이미지를 OTA/FOTA에서 거부.

Sheet 기능 비교
A1: M2M-AT vs OTH-AT 기능 구현 비교
A2: 빌드 시 Kconfig AT_MODEM_CMDSET로 한쪽 명령 세트만 링크. 하단 공용 구현은 두 빌드가 같은 코드를 사용. 시험 결과 '해당없음' = 그 빌드에 기능 없음
A4: 영역 | B4: 기능 | C4: M2M-AT 명령 | D4: OTH-AT 명령 | E4: 공용 / 구현 모듈 | F4: 차이점 | G4: M2M 시험 | H4: OTH 시험
A5: 기본 | B5: 통신 확인 / 에코 | C5: AT, ATE | D5: AT, ATE | E5: cmd_special.c | F5: 동일 | G5: 검증완료 | H5: 검증완료
A6: 기본 | B6: 버전 / MAC | C6: SYS_VER, SYS_MAC | D6: SWVER, MAC, MIB 32/33 | E6: esp_app_desc | F6: M2M은 고객코드(AC0) 필드 추가 | G6: 검증완료 | H6: 검증완료
A7: 기본 | B7: 재부팅 / 공장초기화 | C7: SYS_RST, SYS_FACTORY | D7: RESET, FACRESET | E7: cmd_sys.c (NV 삭제) | F7: OTH FACRESET 1은 다음 부팅 시 공장 SoftAP. OTH는 AWS 파일도 삭제 | G7: SYS_FACTORY 미검증 | H7: 검증완료
A8: 기본 | B8: 설정 속성 조회/변경 | C8: SYS_CONF (Appendix A) | D8: MIB / SETMIB (Appendix B) | E8: at_nvs_kv.c | F8: 인덱스 체계 다름. OTH MIB 18/19는 AWS 토픽 modelId/deviceGroup 겸용 | G8: 검증완료 | H8: 검증완료
A9: 기본 | B9: UART 속도 / 이벤트 끄기 | C9: SYS_UART | D9: SETMIB 36, EVTDEL | E9: at_uart.c / at_event.c | F9: OTH만 이벤트 끄기(EVTDEL) | G9: 검증완료 | H9: 검증완료
A10: 기본 | B10: 절전 / 안테나 / 송신출력 / 국가 | C10: SYS_LSLEEP, SYS_ANTENNA, SYS_COUNTRY | D10: HWPS, ANTVER/SETANT, TXGAIN, COUNTRY | E10: esp_wifi | F10: OTH만 TXGAIN | G10: 검증완료 | H10: 검증완료
A11: 기본 | B11: 딥슬립 | C11: SYS_DSLEEP | D11: - | E11: - | F11: M2M 문서 본문 공백으로 미구현 | G11: 미구현 | H11: 해당없음
A12: Wi-Fi | B12: 모드 / PHY | C12: WF_MODE | D12: MODE (802.11 b/g/n) | E12: cmd_wifi.c | F12: OTH는 모드 명령 없이 접속/APSTART가 자동 전환. OTH MODE는 PHY 프로토콜 | G12: 검증완료 | H12: 검증완료
A13: Wi-Fi | B13: 스캔 | C13: WF_SCAN | D13: SCAN | E13: cmd_wifi.c | F13: 출력 형식만 다름 | G13: 검증완료 | H13: 검증완료
A14: Wi-Fi | B14: STA 접속 / 해제 | C14: WF_CONN, WF_DISCONN | D14: CRYPTO/PSK/ASSOCIATE, SCONN, DISASSOCIATE | E14: at_wifi_sta_join | F14: WEP 양쪽 모두 거부(EN 18031-1) | G14: 검증완료 | H14: 검증완료
A15: Wi-Fi | B15: 자동 재접속 / 프로필 | C15: WF_APMODE | D15: AUCONMODE, SMODE | E15: WF_APMODE 저장소 | F15: OTH는 링크 끊김 시 5초 간격 재접속 | G15: 검증완료 | H15: 검증완료
A16: Wi-Fi | B16: IP 설정 / 상태 | C16: WF_IPSTATUS | D16: IPCONFIG, NWSTATUS | E16: at_wifi_set_station_ip | G16: 검증완료 | H16: 검증완료
A17: Wi-Fi | B17: Enterprise(802.1X) | C17: WF_EAPCONF, WF_EAPCERT | D17: EAPSET, EAPCERT | E17: esp_eap_client | F17: M2M은 실 802.1X AP+RADIUS로 검증, OTH는 명령 단위만 | G17: 검증완료 | H17: 부분검증
A18: Wi-Fi | B18: SoftAP | C18: WF_APSTART, WF_APSTATION | D18: APSTART/APSTOP, APNSET, APLEASEIP | E18: at_wifi_start_softap | F18: open SoftAP는 Kconfig 허용 시만 | G18: 검증완료 | H18: 검증완료
A19: Wi-Fi | B19: DHCP 서버 | C19: NET_DHCPS, NET_DHCP | D19: DHCPDSTART/STOP, APLEASEIP | E19: esp_netif DHCPS | G19: 검증완료 | H19: 검증완료
A20: Wi-Fi | B20: WPS | C20: WF_WPS | D20: WPS_PBC/PIN/CANCEL | E20: esp_wps | F20: 실제 WPS AP 페어링은 양쪽 미시험 | G20: 검증완료 | H20: 검증완료
A21: Wi-Fi | B21: BLE 프로비저닝 | C21: BLE_PROV, BLE_POP | D21: - | E21: cmd_ble_prov.c | F21: OTH는 SoftAP 페어링 서버 사용 | G21: BLE_PROV 미검증 | H21: 해당없음
A22: Wi-Fi | B22: IBSS / WDS / P2P | C22: - | D22: ADSTART, WDS, P2P_* | E22: - | F22: ESP32-C3/IDF 미지원 | G22: 해당없음 | H22: 미지원
A23: TCP/IP | B23: 소켓 연결 / 서버 / 송수신 | C23: NET_CONN, NET_SERVER, NET_SEND, NET_DISCONN, NET_STATUS | D23: SOCKET, CONNECT, BIND/LISTEN, SEND/SENDTO, CLOSE, LSTATUS | E23: net_link.c (M2M) / oth_sock.c (OTH) | F23: OTH는 소켓 번호 체계(TCP 0-2, UDP 3-5, SSL 6) 별도 엔진 | G23: 검증완료 | H23: 검증완료
A24: TCP/IP | B24: SSL 클라이언트 / 서버 | C24: NET_CONN ssl, NET_SERVER ssl | D24: SSL_CONNECT/SEND/CLOSE, SSL_SVR_* | E24: esp_tls | F24: OTH SSL_SVR는 실 TLS 클라이언트 접속 미시험 | G24: 검증완료 | H24: 부분검증
A25: TCP/IP | B25: 투명(데이터) 모드 | C25: NET_DTMODE | D25: DATA_SOCKET, DATA_INTERVAL | E25: at_uart passthrough | G25: 검증완료 | H25: 검증완료
A26: TCP/IP | B26: Ping / DNS / Keepalive | C26: NET_PING, NET_DNS | D26: PING, DNSQUERY, TCPKEEP, NW_CONN | E26: lwip | F26: OTH만 TCPKEEP(단위 초로 결정) | G26: 검증완료 | H26: 검증완료
A27: 서비스 | B27: SNTP | C27: NET_SNTP, NET_SNTPCONF | D27: SNTP, SNTP_GET/SET | E27: cmd_net_svc.c | F27: OTH AWS는 sndDate용으로 자동 동기화 | G27: 검증완료 | H27: 검증완료
A28: 서비스 | B28: HTTP 클라이언트 / 다운로드 | C28: NET_HTTPGET/POST/SET/HEADER/STOP, NET_HTTPDOWNLOAD | D28: HTTPGET/POST/SET/HEADER/STOP, HTTP_DOWNLOAD | E28: cmd_http.c | F28: 개인키 파일은 양쪽 모두 암호화 NVS 저장 | G28: 검증완료 | H28: 검증완료
A29: 서비스 | B29: 저장 파일 조회 | C29: NET_FILELIST, NET_FILEINFO | D29: - | E29: fs_store.c | F29: OTH는 웹 UI로만 | G29: 검증완료 | H29: 해당없음
A30: 서비스 | B30: 웹 설정 서버 | C30: NET_HTTPDSTART/STOP/CONF | D30: HTTPD_START/STOP, HTTPD_IDPW | E30: cmd_httpd.c + web_auth.c | F30: 비밀번호 해시 저장·조회 마스킹(OTH 문서는 평문 → 추후 검토) | G30: 검증완료 | H30: 검증완료
A31: 서비스 | B31: FTP 계정 | C31: - | D31: FTPC_SET/GET | E31: NV 저장 | F31: FTP 클라이언트 자체는 없음 | G31: 해당없음 | H31: 검증완료
A32: 서비스 | B32: DDNS / UPnP / LPD | C32: - | D32: DDNS_*, UPNP_*, LPD_* | E32: - | F32: 범위 외 | G32: 해당없음 | H32: 미지원
A33: MQTT | B33: 브로커 설정 / 접속 / 발행 / 구독 | C33: MQTT_CONF, MQTT_ALPN, MQTT_CONN, MQTT_PUB, MQTT_SUB, MQTT_CLEAN, MQTT_STATUS | D33: MQTT_GET/SET, MQTT_CERT, MQTT_CONNECT, MQTT_PUB, MQTT_SUB | E33: esp-mqtt | F33: M2M은 mqtts/mTLS/wss/ALPN까지 로컬 브로커 검증, OTH는 persistence 0/1/2·자동 구독 | G33: 검증완료 | H33: 검증완료
A34: AWS | B34: 페어링(서버정보 수신) | C34: AWS_PAIR (폐기, 스텁) | D34: SoftAP 페어링 서버 TCP 47000 (OTH Platform) | E34: oth_pairing.c (OTH 전용) | F34: OTH만 앱→모듈 서버정보·AP정보 전달 구현 | G34: 기타 | H34: 미검증
A35: AWS | B35: 장치 인증 / 인증서 발급 | C35: AWS_CLAIMCERT, AWS_PROVISION, AWS_CERT (Fleet Provisioning by Claim) | D35: 인증서버 토큰·인증서 발급 (/register/token, /register/auth), A001 갱신 | E35: cmd_aws.c (M2M) / cmd_oth_aws.c (OTH) | F35: 방식이 완전히 다름: M2M은 AWS 표준 Claim 방식, OTH는 OTH Platform 인증서버 | G35: 검증완료 | H35: 검증완료
A36: AWS | B36: 접속 / 해제 | C36: AWS_CONN, AWS_DISC | D36: 자동(IP 획득 시) + AWS_SEND=A100, AWS_IND | E36: esp-mqtt | F36: OTH는 호스트 명령 없이 모듈이 자동 접속·재시도, LWT(A102) | G36: 검증완료 | H36: 검증완료
A37: AWS | B37: 발행 / 수신 | C37: AWS_PUB, AWS_SUB (임의 토픽) | D37: AWS_SEND / AWS_RECV (고정 토픽·메시지 봉투) | E37: esp-mqtt | F37: OTH 토픽 <root>/{Conn|Event|Control|Lwt}/<group>/<model>/<clientId> | G37: 검증완료 | H37: 검증완료
... A46: 보안 | B46: EN 18031-1 공통 기능 | C46: 웹 로그인 강화, NVS 암호화, TLS 1.2+/1.3, 약한 인증서 거부, BLE PoP | D46: 동일 (공용 코드) | E46: web_auth.c, fs_store.c 등 | F46: OTH 문서 평문 표시 항목은 마스킹 유지(추후 검토) | G46: 검증완료 | H46: 검증완료

Sheet M2M 명령 결과
A1: M2M-AT 명령별 구현/시험 결과
A2: 출처: ESP32_C3/doc/M2M-AT_Command Set_status.xlsx (최종 갱신 2026-09-27). 상태는 이 문서 기준으로 통일(검증필요→미검증, 구현필요→미구현)
A4: No | B4: 장 | C4: 명령 (AT*M2M*) | D4: 기능 | E4: 상태 | F4: 시험 근거 / 비고 | G4: 원 상태(기타)
A5: 1 | B5: 2. Basic AT | C5: AT | D5: 호스트-모듈 통신 확인(핑 테스트) | E5: 검증완료 | F5: 2026-08-29 COM7 실기 라운드트립 확인.
A6: 2 | B6: 2. Basic AT | C6: ATE | D6: 커맨드 에코 on/off | E6: 검증완료 | F6: ATE1 실기 확인.
A7: 3 | B7: 2. Basic AT | C7: ATV | D7: 문서 목차에만 언급, 본문에 커맨드 정의 없음 | E7: 기타 | F7: 코드상 no-op 스텁으로만 존재. 스펙 문서에 실제 동작 정의가 없어 무엇을 검증해야 할지 불명 — 문서 보완 선행 필요. | G7: 기타
A8: 4 | B8: 2. Basic AT | C8: SYS_VER | D8: 펌웨어 버전/빌드시각 조회 | E8: 검증완료 | F8: [2026-09-26] M2M-AT Command Set v2.0 / M2M_SW Release Naming Guide v2.0 반영: 응답에 <customer_code> 3번째 필드 추가(M2M_FW_CUSTOMER, 예 AC0). *M2M*SYS_VER:OK 01.00 2026-09-26-13:00:58 AC0 로 실기 확인. PROJECT_VER도 이 시점부터 01.00 형식으로 전환(이전 1.0.x 계열 폐기).
A9: 5 | B9: 2. Basic AT | C9: SYS_MAC | D9: MAC 주소 조회 | E9: 검증완료 | F9: 실기 확인.
A10: 6 | B10: 2. Basic AT | C10: SYS_RST | D10: 모듈 재부팅 | E10: 검증완료 | F10: 실제 리부팅(크래시 아님) 확인됨.
A11: 7 | B11: 2. Basic AT | C11: SYS_FACTORY | D11: 플래시 설정 공장초기화+재부팅 | E11: 미검증 | F11: 구현은 되어 있으나 파괴적 동작이라 README 실기 검증 목록에서 제외된 것으로 보임. 실기 검증 필요.
A12: 8 | B12: 2. Basic AT | C12: SYS_LSLEEP | D12: 절전(파워세이브) 정책 조회/설정 | E12: 검증완료 | F12: [2026-09-26 실기 검증] COM7 실기: mode 1/3 설정 시 wifi 로그로 실제 esp_wifi_set_ps() 적용 확인, query로 값 유지 확인, mode=2 ERROR 0, 잘못된 값(9) ERROR 2 확인. mode=0 설정 후 SYS_RST로 재부팅해도 at_wifi_init()이 저장값을 재적용해 SYS_LSLEEP=? 가 0을 유지함을 확인(영속성 검증).
A13: 9 | B13: 2. Basic AT | C13: SYS_DSLEEP | D13: 딥슬립 관련 커맨드(추정) | E13: 미구현 | F13: 스펙 문서 자체가 제목만 있고 본문 내용이 비어 있음(원본 docx 공백). 문서 보완이 먼저 필요하며, 코드도 미구현.
A14: 10 | B14: 2. Basic AT | C14: SYS_ANTENNA | D14: 온보드/외장 안테나 선택 | E14: 검증완료 | F14: [2026-09-26 실기 검증] COM7 실기: 기본값 0 확인, type=0 재설정 성공, type=1 ERROR 0, 재조회 시 0 유지, 잘못된 값(5) ERROR 2 확인.
A15: 11 | B15: 2. Basic AT | C15: SYS_UART | D15: UART 보레이트 조회/설정(플래시 저장) | E15: 검증완료 | F15: 115200 get/set 실기 확인.
A16: 12 | B16: 2. Basic AT | C16: SYS_CONF | D16: Appendix A 속성 인덱스 get/set | E16: 검증완료 | F16: get/set/예약 인덱스 오류케이스까지 실기 확인. 단 Appendix A의 인덱스 33~39 각 항목을 낱낱이 개별 검증한 로그는 없음.
A17: 13 | B17: 2. Basic AT | C17: SYS_COUNTRY | D17: 국가/규제 도메인 코드 설정 | E17: 검증완료 | F17: KR/US get/set 실기 확인. ※ ESP32-C3는 2.4GHz 전용 칩이라 Appendix B의 5GHz 채널표는 이 하드웨어에는 물리적으로 적용 불가(기타 항목 참조).
A18: 14 | B18: 3. Wi-Fi 공통 | C18: WF_MODE | D18: Wi-Fi 모드(init/STA/AP/STA+AP) 설정 | E18: 검증완료 | F18: get/set 실기 확인.
A19: 15 | B19: 3. Wi-Fi 공통 | C19: WF_APMODE | D19: 저장된 프로파일로 자동 재접속(전원인가/재연결 시) | E19: 검증완료 | F19: [2026-09-09 실기 검증, README Phase 7] query/erase 라운드트립과 type 2→1→0(SoftAP 저장→재현→초기화) 전체 라운드트립 실기 확인.
... A55: 51 | B55: 6.4 MQTT | C55: MQTT_CLEAN | D55: MQTT 연결 해제+리소스 반환 | E55: 검증완료 | F55: 정상 해제 및 비정상단절 알림 억제 확인.
A56: 52 | B56: 6.5 AWS | C56: AWS_PAIR | D56: 커스텀 프로비저닝 서버 페어링 | E56: 기타 | F56: [2026-09-14 결정] 커스텀 프로비저닝 프로토콜을 새로 설계하는 대신 Fleet Provisioning by Claim으로 일원화하기로 결정 -- 코드는 기존 스텁 그대로 유지(제거하지 않음), M2M-AT Command Set.docx v1.3에 "Note (deprecated)" 문구 추가해 AWS_CLAIMCERT/AWS_PROVISION 사용을 권장하도록 갱신. | G56: 기타(폐기 결정)
A57: 53 | B57: 6.5 AWS | C57: AWS_CLAIMCERT | D57: Claim 인증서/키/CA 파일 등록 | E57: 검증완료 | F57: [2026-09-13 재검증] 실 AWS 계정(ap-southeast-2) 대상 Fleet Provisioning by Claim 전체 라운드트립 완주: claim cert mTLS 접속 -> $aws/certificates/create/json 요청/응답 -> $aws/provisioning-templates/.../provision/json 등록 -> AWS_PROVISION:DONE "esp32-<SerialNumber>". 테스트 중 실기 코드 버그 2…
A58: 54 | B58: 6.5 AWS | C58: AWS_PROVISION | D58: Claim 인증서로 정식 인증서 발급(Fleet Provisioning) | E58: 검증완료 | F58: [2026-09-13 재검증] AWS_PROVISION:DONE "esp32-<SerialNumber>" 까지 실기 확인. 과정에서 실기 버그 3건 발견/수정: MQTT_EVENT_DATA 프래그먼트 재조립 누락(버퍼 2200->6144), 그로 인한 태스크 스택 오버플로우(8192->16384), certificateOwnershipToken 300바이트 버퍼 절단(464자 토큰용으로 600으로 증설). 상세는 AWS_CLAIMCERT 답변 참조. [202…
A59: 55 | B59: 6.5 AWS | C59: AWS_CERT | D59: AWS IoT 인증서 상태 조회/발급/폐기 | E59: 검증완료 | F59: [2026-09-13 재검증] AWS_PROVISION 완주 후 AWS_CERT=? 조회로 state=1, thingName="esp32-9ccc01c0c8e4", endpoint 정상 저장 확인.
A60: 56 | B60: 6.5 AWS | C60: AWS_CONN | D60: AWS IoT Core 접속(mTLS) | E60: 검증완료 | F60: [2026-09-13 재검증] 정식 발급된 디바이스 인증서로 AWS_CONN 실기 접속 성공 (esp-x509-crt-bundle이 AWS ATS 루트를 공개 CA로 정상 검증).
A61: 57 | B61: 6.5 AWS | C61: AWS_DISC | D61: AWS IoT Core 접속 해제 | E61: 검증완료 | F61: [2026-09-13 재검증] AWS_DISC 실기 확인 (claim 연결 종료 1회, 디바이스 연결 종료 1회 모두 DONE).
A62: 58 | B62: 6.5 AWS | C62: AWS_PUB | D62: AWS IoT 토픽 발행(멀티라인 payload) | E62: 검증완료 | F62: [2026-09-13 재검증] esp32test/ping 토픽에 AWS_PUB(QoS1) 실기 확인, AWS_PUB:DONE 수신.
A63: 59 | B63: 6.5 AWS | C63: AWS_SUB | D63: AWS IoT 토픽 구독 | E63: 검증완료 | F63: [2026-09-13 재검증] 동일 토픽 AWS_SUB 후 AWS_PUB로 발행한 메시지가 AWS_MSG:DONE으로 정상 수신됨 (실 AWS IoT Core 라운드트립).
A64: 60 | B64: 6.6 OTA | C64: OTA_CHECK | D64: 서버 펌웨어 버전 확인(부분 다운로드) | E64: 검증완료 | F64: 실 2-바이너리 OTA 사이클로 1.0.0→1.0.1 버전 비교 확인.
A65: 61 | B65: 6.6 OTA | C65: OTA_UPDATE | D65: 펌웨어 다운로드+플래시(자동 재부팅 없음) | E65: 검증완료 | F65: 실기 다운로드+플래시+SYS_RST 후 신버전 부팅까지 확인. 미검사 URL 거부(reason 4) 가드도 확인.
A66: 62 | B66: 6.2 HTTP Client | C66: NET_FILELIST | D66: 저장된 파일 목록 조회 | E66: 검증완료 | F66: [2026-09-14] 실기 확인: AT*M2M*NET_FILELIST -> ca.pem 1785 정상 목록 표시. 최초 구현 시 static 없이 fs_store_entry_t entries[32]를 at_uart_rx 태스크(스택 4096바이트) 지역변수로 잡아 Guru Meditation(Stack protection fault)으로 보드가 리셋되는 실기 버그를 발견 -- cmd_wifi.c의 WF_EAPCERT 인증서 버퍼와 동일하게 static으로 변…
A67: 63 | B67: 6.2 HTTP Client | C67: NET_FILEINFO | D67: 파일 크기/인증서 지문 조회 | E67: 검증완료 | F67: [2026-09-14] 실기 확인: AT*M2M*NET_FILEINFO=ca.pem -> 크기+실제 SHA-256 지문 정상 반환(웹 UI TLS Certificates 화면과 동일 값). 없는 파일 조회 시 ERROR 1, 인자 누락 시 ERROR 2 확인.
A68: 64 | B68: 6.4 MQTT | C68: MQTT_STATUS | D68: MQTT 링크 실시간 연결 상태 조회 | E68: 검증완료 | F68: [2026-09-14] 실기 확인: 미설정 시 IND 없이 OK만 반환 -> MQTT_CONF+MQTT_CONN으로 로컬 브로커(192.168.10.2:1883) 연결 후 재조회 시 configured=1 connected=1 정상 표시.
... A70: 66 | B70: 3.5 BLE Provisioning | C70: BLE_POP | D70: BLE 프로비저닝 PoP(proof-of-possession) 조회/설정 | E70: 검증완료 | F70: [2026-09-27 EN 18031-1] 신규(문서 Rev 1.8). 첫 부팅 시 하드웨어 RNG 로 12자(2-9, A-Z 중 I/L/O 제외) 생성·NVS 저장, Query 로 조회(라벨/QR 인쇄용), Set 으로 8~32자 값 교체. reason 1-형식 오류, 2-프로비저닝 창 열림. COM7 실기 확인: 첫 부팅 생성, 재부팅 후 동일 값 유지, 짧은 값 거부(ERROR 1). 폰 앱으로 새 PoP 사용 세션은 미검증.

Sheet OTH 명령 결과
A1: OTH-AT 명령별 구현/시험 결과
A2: 출처: OTH_ESP32_C3/doc/OTH-AT_Command_Status.xlsx (2026-10-05) + AWS 볼륨은 2026-10-06 OTH Platform 재구현 결과로 교체
A4: 문서 | B4: 장 | C4: 명령 (AT*OTH*) | D4: 상태 | E4: 구현 기반 | F4: 시험 근거 / 비고
A5: Essentials | B5: 2 | C5: AT / ATE | D5: 검증완료 | E5: cmd_special.c (공용)
A6: Essentials | B6: 2 | C6: SWVER | D6: 검증완료 | E6: esp_app_desc | F6: "01.00" 형식
A7: Essentials | B7: 2 | C7: MAC | D7: 검증완료 | E7: SYS_MAC
A8: Essentials | B8: 2 | C8: RESET | D8: 검증완료 | E8: esp_restart | F8: mode 0/1 모두 플래시 부팅
A9: Essentials | B9: 2 | C9: FACRESET | D9: 검증완료 | E9: SYS_FACTORY NV 삭제 | F9: mode 1: 다음 부팅 시 공장 SoftAP(OTH_xxxxxx, open, ch1). 재부팅하지 않음 / 2026-10-06: AWS 인증서·RootCA 파일도 삭제
A10: Essentials | B10: 2 | C10: EVTDEL | D10: 검증완료 | E10: at_event | F10: NV 저장, RECV 계열 데이터 알림도 포함
A11: Essentials | B11: 2 | C11: FWUPGRADE | D11: 검증완료 | E11: 신규 (cmd_oth_fwup.c) | F11: XMODEM-CRC 128/1K, bank 1=ota_0, 2=ota_1, 실행 중 bank 거부. 실패 시 FWUPGRADE:ERROR <code> (문서에 없는 줄 추가)
A12: Essentials | B12: 2 | C12: HWPS | D12: 검증완료 | E12: SYS_LSLEEP | F12: 0 자동(modem sleep), 1 off, 2 max. HWPSIND는 미보고(드라이버 이벤트 없음)
A13: Essentials | B13: 2 | C13: ANTVER / SETANT | D13: 검증완료 | E13: SYS_ANTENNA | F13: 외부 안테나(1)는 보드에 없어 ERROR 5
A14: Essentials | B14: 2 | C14: TXGAIN | D14: 검증완료 | E14: esp_wifi_set_max_tx_power | F14: 0.25 dB 단위 감쇠, 무선 시작 시 재적용
A15: Essentials | B15: 2 | C15: COUNTRY | D15: 검증완료 | E15: SYS_COUNTRY | F15: 드라이버가 아는 2글자 코드 전부. 3글자(USE 등) 불가
A16: Essentials | B16: 2 | C16: MIB / SETMIB | D16: 검증완료 | E16: 신규 (cmd_oth_svc.c) | F16: 비밀번호(7,11) 마스킹, WEP(6,8)·RTS/CTS/Frag(64-66)·103 null. SETMIB 102/105/106 저장만
A17: Essentials | B17: 2 | C17: UARTPROTO (Optional) | D17: 미지원 | F17: 바이너리 UART 프로토콜 미구현 (M2M과 동일)
A18: Essentials | B18: 3.1 | C18: MODE | D18: 검증완료 | E18: esp_wifi_set_protocol | F18: 1(B+G) 2(B+G+N) 3(B)만. 0/4/5-7 ERROR 5
A19: Essentials | B19: 3.1 | C19: SCAN | D19: 검증완료 | E19: WF_SCAN 로직 | F19: SCANIND/SCANRESULT, 공백 SSID 따옴표, 숨김 NULL, WPA3는 WPA2 코드로
A20: Essentials | B20: 3.1 | C20: CRYPTO / PSK / ASSOCIATE | D20: 검증완료 | E20: at_wifi_sta_join | F20: WEP(key_mgmt 1) 거부
A21: Essentials | B21: 3.1 | C21: WEP | D21: 미지원 | F21: 보안상 거부(M2M과 동일) - 추후 검토
A22: Essentials | B22: 3.1 | C22: DISASSOCIATE | D22: 검증완료 | E22: WF_DISCONN
A23: Essentials | B23: 3.1 | C23: SCONN | D23: 검증완료 | E23: at_wifi_sta_join | F23: 선택 필드는 모양으로 구분(MAC=bssid, 1-4=WEP idx)
A24: Essentials | B24: 3.1 | C24: AUCONMODE | D24: 검증완료 | E24: WF_APMODE 저장소 | F24: mode 1: 부팅·링크 끊김 시 5초 간격 재접속. type 0-3은 저장·보고만
A25: Essentials | B25: 3.1 | C25: SMODE | D25: 검증완료 | E25: WF_APMODE 프로필 | F25: 응답 이름은 문서대로 *OTH*MODE
A26: Essentials | B26: 3.1 | C26: EAPSET / EAPCERT (Optional) | D26: 검증완료 | E26: WF_EAPCONF/EAPCERT | F26: leap 미지원(ESP-IDF). 802.1X AP 실접속은 이번에 미시험
A27: Essentials | B27: 3.1 | C27: NWSTATUS | D27: 검증완료 | E27: 신규 | F27: 미접속·SoftAP 없음이면 ERROR 4
A28: Essentials | B28: 3.2 | C28: APSTART / APSTOP | D28: 검증완료 | E28: at_wifi_start_softap | F28: WEP 불가, open은 Kconfig 허용 시만
A29: Essentials | B29: 3.2 | C29: APNSET / APLEASEIP | D29: 검증완료 | E29: esp_netif DHCPS | F29: 기본 192.168.0.1/24, 10~254. DHCP 서버는 최대 100개 주소만 배정
A30: Essentials | B30: 3.2 | C30: DHCPDSTART / DHCPDSTOP | D30: 검증완료 | E30: esp_netif DHCPS
A31: Essentials | B31: 3.3 | C31: WPS_PBC / WPS_PIN / WPS_CANCEL | D31: 검증완료 | E31: esp_wps | F31: PBC의 bssid 지정 불가(ERROR 5). 실제 WPS AP 페어링은 미시험
A32: Essentials | B32: 3.3 | C32: ADSTART / ADSTOP (Optional) | D32: 미지원 | F32: ESP32-C3는 IBSS 미지원
A33: Essentials | B33: 3.3 | C33: WDS | D33: 미지원 | F33: ESP-IDF 미지원
A34: Essentials | B34: 3.3 | C34: P2P_* (Optional) | D34: 미지원 | F34: ESP32-C3 Wi-Fi Direct 미지원
A35: Essentials | B35: 4 | C35: IPCONFIG | D35: 검증완료 | E35: at_wifi_set_station_ip
A36: Essentials | B36: 4 | C36: SOCKET / CLOSE | D36: 검증완료 | E36: oth_sock.c | F36: TCP 0-2, UDP 3-5, SSL 6
A37: Essentials | B37: 4 | C37: CONNECT | D37: 검증완료 | E37: oth_sock.c | F37: CONNECTED / TIMEOUT(9초) / REJECTED
A38: Essentials | B38: 4 | C38: BIND / LISTEN / LSTATUS / DISCONNECT | D38: 검증완료 | E38: oth_sock.c | F38: 서버 소켓당 클라이언트 4개
A39: Essentials | B39: 4 | C39: SEND / SENDTO | D39: 검증완료 | E39: oth_sock.c | F39: 바이트 스터핑, 최대 1460바이트
A40: Essentials | B40: 4 | C40: TCPKEEP | D40: 검증완료 | E40: lwip keepalive | F40: keep_time 단위를 초로 정함(문서에 단위 없음)
A41: Essentials | B41: 4 | C41: NW_CONN | D41: 검증완료 | E41: oth_sock.c
...

Sheet OTH Platform 시험
A1: OTH Platform 시험 기록 (2026-10-06, COM7 보드)
A2: 환경: ESP32-C3 보드(COM7), AP kangaps25, 모의 인증서버(PC 10.128.82.113:8080), MQTT broker.emqx.io(엔드포인트 대용), PC paho 클라이언트(클라우드 역할). 토픽 루트 OTHERS, MIB18=C545, MIB19=Air01
A4: ID | B4: 시험 항목 | C4: 방법 | D4: 기대 결과 | E4: 실제 결과 | F4: 판정
A5: P-01 | B5: 인증 단계 | C5: 모의 인증서버(PC LAN, http) | D5: token 발급 → 클라이언트ID MAC_토큰, 인증서·키 발급/저장 | E5: AUTHENTICATE/CERTIFICATE/PRIVATE_KEY OK 0, AWS_GET 2 = 9CCC01C0C8E4_T0K3N7f3a | F5: 합격
A6: P-02 | B6: 인증서 오류 | C6: 공개 서비스(httpbin)로 인증서 없는 응답 | D6: CERTIFICATE ERROR 112 | E6: CERTIFICATE ERROR 112 | F6: 합격
A7: P-03 | B7: MQTT 접속 | C7: broker.emqx.io:8883 (TLS, 공개 CA 번들) | D7: ROOTCA OK, CONNECT OK, Control 구독, A100 발행 | E7: A100 수신(V01=100, versionChange false) | F7: 합격
A8: P-04 | B8: 저장 인증서 재사용 | C8: 인증서버 정지 후 재부팅/재접속 | D8: 서버 없이 접속 | E8: AUTHENTICATE~CONNECT OK 0 | F8: 합격
A9: P-05 | B9: 송신 봉투 / apiGroup | C9: AWS_SEND=A110, A130 | D9: Event 토픽, apiGroup 001/003 | E9: 일치, AWS_IND:SEND OK | F9: 합격
A10: P-06 | B10: 수신 attributes | C10: 클라우드 A111 {attributes} | D10: AWS_RECV:A111 23 {...} | E10: AWS_RECV:A111 23 {"A03":"02","A04":"03"} | F10: 합격
A11: P-07 | B11: 수신 평탄화 | C11: 클라우드 A112 (attributes 없음) | D11: values 필드를 JSON으로 | E11: AWS_RECV:A112 17 {"reqType":"all"} | F11: 합격
A12: P-08 | B12: 타 장치 메시지 | C12: deviceId 다른 A111 | D12: 폐기 | E12: 호스트 출력 없음 | F12: 합격
A13: P-09 | B13: 버전 요청 | C13: 클라우드 A502 | D13: 모듈이 A500 자동 응답, 호스트 미전달 | E13: Event A500 (apiGroup 005, V01/V02) | F13: 합격
A14: P-10 | B14: 모듈 FOTA 실패 | C14: A511 잘못된 URL / 잘못된 SHA-256 | D14: A510 102→201→900 | E14: 두 경우 모두 900 errCd 9, 설치 안 함 | F14: 합격
A15: P-11 | B15: 모듈 FOTA 성공 | C15: A511 AES-256-CBC 암호화 이미지 + 올바른 SHA-256 | D15: A510 102→201→202→301, 재부팅, A100 versionChangeW true | E15: ota_1에서 부팅, versionChangeW "true" | F15: 합격
... A25: P-21 | B25: 실서버 | C25: 실제 인증서버 / AWS IoT 엔드포인트 | D25: - | E25: 미시험 | F25: 미시험

Sheet 미검증·추후
A1: 미검증 · 추후 검토 항목
A3: 대상 | B3: 항목 | C3: 상태 | D3: 필요 사항 / 비고
A4: M2M | B4: SYS_DSLEEP | C4: 미구현 | D4: 문서 본문 공백 - 사용자 별도 검토 중
A5: M2M | B5: SYS_FACTORY | C5: 미검증 | D5: 파괴적 동작이라 실기 보류
A6: M2M | B6: BLE_PROV | C6: 미검증 | D6: 폰 앱 완주 로그 미정리, PoP placeholder 교체 필요
A7: M2M | B7: AWS_PAIR | C7: 기타 | D7: 폐기 결정(Fleet Provisioning으로 일원화), 스텁 유지
A8: OTH | B8: 페어링 서버 (TCP 47000) | C8: 미검증 | D8: 앱 또는 별도 Wi-Fi 단말 필요
A9: OTH | B9: A101 등록 해지 | C9: 미검증 | D9: 시험 시 보드 AP 프로필 재입력 필요
A10: OTH | B10: 실 인증서버 / AWS IoT 엔드포인트 | C10: 미검증 | D10: 실서버 정보 필요 (토픽 루트 Kconfig 값 포함)
A11: OTH | B11: SSL_SVR_* | C11: 부분검증 | D11: server.pem 적재 후 실 TLS 클라이언트 접속 필요
A12: OTH | B12: EAPSET/EAPCERT, WPS | C12: 부분검증 | D12: 실 802.1X AP / WPS AP 필요
A13: OTH | B13: UARTPROTO, DDNS/UPnP/LPD, WEP, IBSS/WDS/P2P | C13: 미지원 | D13: 범위 외 또는 하드웨어/보안상 미지원
A14: OTH | B14: COAP 볼륨 | C14: 미구현 | D14: 범위 제외 결정(2026-10-05)
... A18: 등록 | B18: 명령체계 코드 OT | C18: 기타 | D18: M2M_Code Register.xlsx 명령체계코드 시트 등록 필요
